#VRML_SIM R2021b utf8
WorldInfo {
  coordinateSystem "NUE"
}
Viewpoint {
  orientation -0.8359033019038656 -0.5185900090977541 -0.17980565155246395 0.7863736494449995
  position -0.3121556976677087 0.7892745133668301 0.9861171520522594
}
TexturedBackground {
}
TexturedBackgroundLight {
}
RectangleArena {
  floorSize 2 2
}
Robot {
  translation 0 0.13 0
  rotation 1 0 0 1.5708
  children [
    HingeJoint {
      jointParameters HingeJointParameters {
        anchor 0.09 0 0
      }
      endPoint Solid {
        translation 0.09 0 0
        rotation 1 0 0 0
        children [
          HingeJoint {
            jointParameters HingeJointParameters {
              axis 0 0 1
              anchor 0 -0.09 0
            }
            device [
              RotationalMotor {
                name "ServoFrontR"
              }
            ]
            endPoint Solid {
              translation -0.015 -0.19 0
              rotation 0 0 1 1.5708
              children [
                DEF Wheel01 HingeJoint {
                  jointParameters HingeJointParameters {
                    axis 0 1 0
                    anchor 0.1 -0.02 0.09
                  }
                  device [
                    RotationalMotor {
                      name "WheelFrontR"
                    }
                  ]
                  endPoint Solid {
                    translation 0.1 -0.02 0.09
                    children [
                      DEF Wheel01 Shape {
                        appearance GenericTireAppearance {
                        }
                        geometry Cylinder {
                          height 0.04
                          radius 0.04
                        }
                      }
                    ]
                    name "solid(2)"
                    boundingObject USE Wheel01
                    physics Physics {
                    }
                  }
                }
                DEF Joint01 Group {
                  children [
                    Transform {
                      children [
                        Solid {
                          translation 0.1 0 0.03
                          children [
                            DEF Cube01 Shape {
                              appearance MattePaint {
                              }
                              geometry Box {
                                size 0.025 0.06 0.025
                              }
                            }
                          ]
                          boundingObject USE Cube01
                          physics Physics {
                          }
                        }
                      ]
                    }
                    Transform {
                      translation 0 0.048 0.07
                      rotation 1 0 0 1.5708
                      children [
                        Solid {
                          translation 0.1 0 0.03
                          children [
                            DEF Cube02 Shape {
                              appearance MattePaint {
                              }
                              geometry Box {
                                size 0.025 0.06 0.025
                              }
                            }
                          ]
                          name "solid(1)"
                          boundingObject USE Cube02
                          physics Physics {
                          }
                        }
                      ]
                    }
                  ]
                }
              ]
              physics Physics {
              }
            }
          }
          HingeJoint {
            jointParameters HingeJointParameters {
              axis 0 0 1
              anchor 0 0.09 0
            }
            device [
              RotationalMotor {
                name "ServoMiddleR"
              }
            ]
            endPoint Solid {
              translation -0.015 0.19 0
              rotation 0 0 1 1.5708
              children [
                DEF Wheel HingeJoint {
                  jointParameters HingeJointParameters {
                    axis 0 1 0
                    anchor -0.1 -0.02 0.09
                  }
                  device [
                    RotationalMotor {
                      name "WheelMiddleR"
                    }
                  ]
                  endPoint Solid {
                    translation -0.1 -0.02 0.09
                    children [
                      DEF Wheel02 Shape {
                        appearance GenericTireAppearance {
                        }
                        geometry Cylinder {
                          height 0.04
                          radius 0.04
                        }
                      }
                    ]
                    name "solid(2)"
                    boundingObject USE Wheel02
                    physics Physics {
                    }
                  }
                }
                Group {
                  children [
                    Transform {
                      children [
                        Solid {
                          translation -0.1 0 0.03
                          children [
                            DEF Cube01 Shape {
                              appearance MattePaint {
                              }
                              geometry Box {
                                size 0.025 0.06 0.025
                              }
                            }
                          ]
                          boundingObject USE Cube01
                          physics Physics {
                          }
                        }
                      ]
                    }
                    Transform {
                      translation 0 0.048 0.07
                      rotation 1 0 0 1.5708
                      children [
                        Solid {
                          translation -0.1 0 0.03
                          children [
                            DEF Cube02 Shape {
                              appearance MattePaint {
                              }
                              geometry Box {
                                size 0.025 0.06 0.025
                              }
                            }
                          ]
                          name "solid(1)"
                          boundingObject USE Cube02
                          physics Physics {
                          }
                        }
                      ]
                    }
                  ]
                }
              ]
              name "solid(1)"
              physics Physics {
              }
            }
          }
          DEF Shoulder01 Shape {
            appearance MattePaint {
            }
            geometry Box {
              size 0.025 0.2 0.025
            }
          }
        ]
        boundingObject USE Shoulder01
        physics Physics {
        }
      }
    }
    HingeJoint {
      jointParameters HingeJointParameters {
        anchor -0.09 0 0
      }
      endPoint Solid {
        translation -0.09 -2.91896e-07 0
        rotation 0 0 1 3.14159
        children [
          HingeJoint {
            jointParameters HingeJointParameters {
              axis 0 0 1
              anchor 0 -0.09 0
            }
            device [
              RotationalMotor {
                name "ServoMiddleL"
              }
            ]
            endPoint Solid {
              translation -0.015 -0.19 0
              rotation 0 0 1 1.5708
              children [
                DEF Wheel01 HingeJoint {
                  jointParameters HingeJointParameters {
                    axis 0 -1 0
                    anchor 0.1 -0.02 0.09
                  }
                  device [
                    RotationalMotor {
                      name "WheelMiddleL"
                    }
                  ]
                  endPoint Solid {
                    translation 0.1 -0.02 0.09
                    rotation 0 -1 0 0
                    children [
                      DEF Wheel01 Shape {
                        appearance GenericTireAppearance {
                        }
                        geometry Cylinder {
                          height 0.04
                          radius 0.04
                        }
                      }
                    ]
                    name "solid(2)"
                    boundingObject USE Wheel01
                    physics Physics {
                    }
                  }
                }
                DEF Joint01 Group {
                  children [
                    Transform {
                      children [
                        Solid {
                          translation 0.1 0 0.03
                          children [
                            DEF Cube01 Shape {
                              appearance MattePaint {
                              }
                              geometry Box {
                                size 0.025 0.06 0.025
                              }
                            }
                          ]
                          boundingObject USE Cube01
                          physics Physics {
                          }
                        }
                      ]
                    }
                    Transform {
                      translation 0 0.048 0.07
                      rotation 1 0 0 1.5708
                      children [
                        Solid {
                          translation 0.1 0 0.03
                          children [
                            DEF Cube02 Shape {
                              appearance MattePaint {
                              }
                              geometry Box {
                                size 0.025 0.06 0.025
                              }
                            }
                          ]
                          name "solid(1)"
                          boundingObject USE Cube02
                          physics Physics {
                          }
                        }
                      ]
                    }
                  ]
                }
              ]
              physics Physics {
              }
            }
          }
          HingeJoint {
            jointParameters HingeJointParameters {
              axis 0 0 1
              anchor 0 0.09 0
            }
            device [
              RotationalMotor {
                name "ServoFrontL"
              }
            ]
            endPoint Solid {
              translation -0.015 0.19 0
              rotation 0 0 1 1.5708
              children [
                DEF Wheel01 HingeJoint {
                  jointParameters HingeJointParameters {
                    axis 0 -1 0
                    anchor -0.1 -0.02 0.09
                  }
                  device [
                    RotationalMotor {
                      name "WheelFrontL"
                    }
                  ]
                  endPoint Solid {
                    translation -0.1 -0.02 0.09
                    rotation 0 -1 0 0
                    children [
                      DEF Wheel01 Shape {
                        appearance GenericTireAppearance {
                        }
                        geometry Cylinder {
                          height 0.04
                          radius 0.04
                        }
                      }
                    ]
                    name "solid(2)"
                    boundingObject USE Wheel01
                    physics Physics {
                    }
                  }
                }
                DEF Joint01 Group {
                  children [
                    Transform {
                      children [
                        Solid {
                          translation -0.1 0 0.03
                          children [
                            DEF Cube01 Shape {
                              appearance MattePaint {
                              }
                              geometry Box {
                                size 0.025 0.06 0.025
                              }
                            }
                          ]
                          boundingObject USE Cube01
                          physics Physics {
                          }
                        }
                      ]
                    }
                    Transform {
                      translation -0.1 0.048 0.07
                      rotation 1 0 0 1.5708
                      children [
                        Solid {
                          translation 0 0 0.03
                          children [
                            DEF Cube02 Shape {
                              appearance MattePaint {
                              }
                              geometry Box {
                                size 0.025 0.06 0.025
                              }
                            }
                          ]
                          name "solid(1)"
                          boundingObject USE Cube02
                          physics Physics {
                          }
                        }
                      ]
                    }
                  ]
                }
              ]
              name "solid(1)"
              physics Physics {
              }
            }
          }
          DEF Shoulder01 Shape {
            appearance MattePaint {
            }
            geometry Box {
              size 0.025 0.2 0.025
            }
          }
        ]
        name "solid(1)"
        boundingObject USE Shoulder01
        physics Physics {
        }
      }
    }
    HingeJoint {
      jointParameters HingeJointParameters {
        axis 0 1 0
        anchor 0 0.24 0
      }
      endPoint Solid {
        translation 0 0.24 0
        rotation 0 0 0.9999999999999999 1.5707953071795862
        children [
          HingeJoint {
            jointParameters HingeJointParameters {
              axis 0 0 1
              anchor 0 -0.09 0
            }
            device [
              RotationalMotor {
                name "ServoTailR"
              }
            ]
            endPoint Solid {
              translation -0.1 -0.07 0
              rotation 0 0 0.9999999999999999 7.336820926287227e-06
              children [
                DEF Wheel01 HingeJoint {
                  jointParameters HingeJointParameters {
                    axis 0 1 0
                    anchor 0.1 -0.02 0.09
                  }
                  device [
                    RotationalMotor {
                      name "WheelTailR"
                    }
                  ]
                  endPoint Solid {
                    translation 0.1 -0.02 0.09
                    children [
                      DEF Wheel01 Shape {
                        appearance GenericTireAppearance {
                        }
                        geometry Cylinder {
                          height 0.04
                          radius 0.04
                        }
                      }
                    ]
                    name "solid(2)"
                    boundingObject USE Wheel01
                    physics Physics {
                    }
                  }
                }
                DEF Joint01 Group {
                  children [
                    Transform {
                      children [
                        Solid {
                          translation 0.1 0 0.03
                          children [
                            DEF Cube01 Shape {
                              appearance MattePaint {
                              }
                              geometry Box {
                                size 0.025 0.06 0.025
                              }
                            }
                          ]
                          boundingObject USE Cube01
                          physics Physics {
                          }
                        }
                      ]
                    }
                    Transform {
                      translation 0 0.048 0.07
                      rotation 1 0 0 1.5708
                      children [
                        Solid {
                          translation 0.1 0 0.03
                          children [
                            DEF Cube02 Shape {
                              appearance MattePaint {
                              }
                              geometry Box {
                                size 0.025 0.06 0.025
                              }
                            }
                          ]
                          name "solid(1)"
                          boundingObject USE Cube02
                          physics Physics {
                          }
                        }
                      ]
                    }
                  ]
                }
              ]
              physics Physics {
              }
            }
          }
          HingeJoint {
            jointParameters HingeJointParameters {
              axis 0 0 1
              anchor 0 0.09 0
            }
            device [
              RotationalMotor {
                name "ServoTailL"
              }
            ]
            endPoint Solid {
              translation -0.1 0.07 0
              rotation 0 0 -1 3.1415853071795863
              children [
                DEF Wheel01 HingeJoint {
                  jointParameters HingeJointParameters {
                    axis 0 -1 0
                    anchor -0.1 -0.02 0.09
                  }
                  device [
                    RotationalMotor {
                      name "WheelTailL"
                    }
                  ]
                  endPoint Solid {
                    translation -0.1 -0.02 0.09
                    rotation 0 -1 0 0
                    children [
                      DEF Wheel01 Shape {
                        appearance GenericTireAppearance {
                        }
                        geometry Cylinder {
                          height 0.04
                          radius 0.04
                        }
                      }
                    ]
                    name "solid(2)"
                    boundingObject USE Wheel01
                    physics Physics {
                    }
                  }
                }
                DEF Joint01 Group {
                  children [
                    Transform {
                      children [
                        Solid {
                          translation -0.1 0 0.03
                          children [
                            DEF Cube01 Shape {
                              appearance MattePaint {
                              }
                              geometry Box {
                                size 0.025 0.06 0.025
                              }
                            }
                          ]
                          boundingObject USE Cube01
                          physics Physics {
                          }
                        }
                      ]
                    }
                    Transform {
                      translation -0.1 0.048 0.07
                      rotation 1 0 0 1.5708
                      children [
                        Solid {
                          translation 0 0 0.03
                          children [
                            DEF Cube02 Shape {
                              appearance MattePaint {
                              }
                              geometry Box {
                                size 0.025 0.06 0.025
                              }
                            }
                          ]
                          name "solid(1)"
                          boundingObject USE Cube02
                          physics Physics {
                          }
                        }
                      ]
                    }
                  ]
                }
              ]
              name "solid(1)"
              physics Physics {
              }
            }
          }
          DEF Shoulder01 Shape {
            appearance MattePaint {
            }
            geometry Box {
              size 0.025 0.2 0.025
            }
          }
        ]
        name "solid(2)"
        boundingObject USE Shoulder01
        physics Physics {
        }
      }
    }
    DEF Body Group {
      children [
        Transform {
          rotation 0 0 1 1.5708
          children [
            Shape {
              appearance MattePaint {
              }
              geometry Cylinder {
                height 0.2
                radius 0.008
              }
            }
          ]
        }
        Transform {
          translation -2.93856e-07 0.08 0
          rotation 0 0 1 -3.1415853071795863
          children [
            Shape {
              appearance MattePaint {
              }
              geometry Cylinder {
                height 0.4
                radius 0.008
              }
            }
          ]
        }
      ]
    }
  ]
  boundingObject USE Body
  physics Physics {
  }
  controller "robot_controller"
}
